ERROR 2018-01-17 16:08:06,462 base Internal Server Error: /
Traceback (most recent call last):
  File "/usr/local/lib/python2.7/site-packages/django/core/handlers/base.py", line 149, in get_response
    response = self.process_exception_by_middleware(e, request)
  File "/usr/local/lib/python2.7/site-packages/django/core/handlers/base.py", line 147, in get_response
    response = wrapped_callback(request, *callback_args, **callback_kwargs)
  File "/usr/local/lib/python2.7/site-packages/django/views/generic/base.py", line 68, in view
    return self.dispatch(request, *args, **kwargs)
  File "/usr/local/lib/python2.7/site-packages/django/views/generic/base.py", line 88, in dispatch
    return handler(request, *args, **kwargs)
  File "/root/weixinweb/apps/mobile/views.py", line 111, in get
    if not request.user.is_authenticated():
  File "/usr/local/lib/python2.7/site-packages/django/utils/functional.py", line 204, in inner
    self._setup()
  File "/usr/local/lib/python2.7/site-packages/django/utils/functional.py", line 351, in _setup
    self._wrapped = self._setupfunc()
  File "/usr/local/lib/python2.7/site-packages/django/contrib/auth/middleware.py", line 22, in <lambda>
    request.user = SimpleLazyObject(lambda: get_user(request))
  File "/usr/local/lib/python2.7/site-packages/django/contrib/auth/middleware.py", line 10, in get_user
    request._cached_user = auth.get_user(request)
  File "/usr/local/lib/python2.7/site-packages/django/contrib/auth/__init__.py", line 167, in get_user
    user_id = _get_user_session_key(request)
  File "/usr/local/lib/python2.7/site-packages/django/contrib/auth/__init__.py", line 59, in _get_user_session_key
    return get_user_model()._meta.pk.to_python(request.session[SESSION_KEY])
  File "/usr/local/lib/python2.7/site-packages/django/contrib/sessions/backends/base.py", line 50, in __getitem__
    return self._session[key]
  File "/usr/local/lib/python2.7/site-packages/django/contrib/sessions/backends/base.py", line 201, in _get_session
    self._session_cache = self.load()
  File "/usr/local/lib/python2.7/site-packages/django/contrib/sessions/backends/db.py", line 33, in load
    expire_date__gt=timezone.now()
  File "/usr/local/lib/python2.7/site-packages/django/db/models/manager.py", line 122, in manager_method
    return getattr(self.get_queryset(), name)(*args, **kwargs)
  File "/usr/local/lib/python2.7/site-packages/django/db/models/query.py", line 381, in get
    num = len(clone)
  File "/usr/local/lib/python2.7/site-packages/django/db/models/query.py", line 240, in __len__
    self._fetch_all()
  File "/usr/local/lib/python2.7/site-packages/django/db/models/query.py", line 1074, in _fetch_all
    self._result_cache = list(self.iterator())
  File "/usr/local/lib/python2.7/site-packages/django/db/models/query.py", line 52, in __iter__
    results = compiler.execute_sql()
  File "/usr/local/lib/python2.7/site-packages/django/db/models/sql/compiler.py", line 837, in execute_sql
    sql, params = self.as_sql()
  File "/usr/local/lib/python2.7/site-packages/django/db/models/sql/compiler.py", line 389, in as_sql
    where, w_params = self.compile(self.where) if self.where is not None else ("", [])
  File "/usr/local/lib/python2.7/site-packages/django/db/models/sql/compiler.py", line 366, in compile
    sql, params = node.as_sql(self, self.connection)
  File "/usr/local/lib/python2.7/site-packages/django/db/models/sql/where.py", line 79, in as_sql
    sql, params = compiler.compile(child)
  File "/usr/local/lib/python2.7/site-packages/django/db/models/sql/compiler.py", line 366, in compile
    sql, params = node.as_sql(self, self.connection)
  File "/usr/local/lib/python2.7/site-packages/django/db/models/lookups.py", line 157, in as_sql
    lhs_sql, params = self.process_lhs(compiler, connection)
  File "/usr/local/lib/python2.7/site-packages/django/db/models/lookups.py", line 150, in process_lhs
    db_type = self.lhs.output_field.db_type(connection=connection)
  File "/usr/local/lib/python2.7/site-packages/django/db/models/fields/__init__.py", line 625, in db_type
    return connection.data_types[self.get_internal_type()] % data
  File "/usr/local/lib/python2.7/site-packages/django/utils/functional.py", line 33, in __get__
    res = instance.__dict__[self.name] = self.func(instance)
  File "/usr/local/lib/python2.7/site-packages/django/db/backends/mysql/base.py", line 184, in data_types
    if self.features.supports_microsecond_precision:
  File "/usr/local/lib/python2.7/site-packages/django/utils/functional.py", line 33, in __get__
    res = instance.__dict__[self.name] = self.func(instance)
  File "/usr/local/lib/python2.7/site-packages/django/db/backends/mysql/features.py", line 53, in supports_microsecond_precision
    return self.connection.mysql_version >= (5, 6, 4) and Database.version_info >= (1, 2, 5)
  File "/usr/local/lib/python2.7/site-packages/django/utils/functional.py", line 33, in __get__
    res = instance.__dict__[self.name] = self.func(instance)
  File "/usr/local/lib/python2.7/site-packages/django/db/backends/mysql/base.py", line 359, in mysql_version
    with self.temporary_connection():
  File "/usr/local/lib/python2.7/contextlib.py", line 17, in __enter__
    return self.gen.next()
  File "/usr/local/lib/python2.7/site-packages/django/db/backends/base/base.py", line 564, in temporary_connection
    cursor = self.cursor()
  File "/usr/local/lib/python2.7/site-packages/django/db/backends/base/base.py", line 231, in cursor
    cursor = self.make_debug_cursor(self._cursor())
  File "/usr/local/lib/python2.7/site-packages/django/db/backends/base/base.py", line 204, in _cursor
    self.ensure_connection()
  File "/usr/local/lib/python2.7/site-packages/django/db/backends/base/base.py", line 199, in ensure_connection
    self.connect()
  File "/usr/local/lib/python2.7/site-packages/django/db/utils.py", line 95, in __exit__
    six.reraise(dj_exc_type, dj_exc_value, traceback)
  File "/usr/local/lib/python2.7/site-packages/django/db/backends/base/base.py", line 199, in ensure_connection
    self.connect()
  File "/usr/local/lib/python2.7/site-packages/django/db/backends/base/base.py", line 171, in connect
    self.connection = self.get_new_connection(conn_params)
  File "/usr/local/lib/python2.7/site-packages/django/db/backends/mysql/base.py", line 264, in get_new_connection
    conn = Database.connect(**conn_params)
  File "/usr/local/lib/python2.7/site-packages/MySQLdb/__init__.py", line 81, in Connect
    return Connection(*args, **kwargs)
  File "/usr/local/lib/python2.7/site-packages/MySQLdb/connections.py", line 193, in __init__
    super(Connection, self).__init__(*args, **kwargs2)
OperationalError: (2003, "Can't connect to MySQL server on '127.0.0.1' (111)")
WARNING 2018-01-17 16:08:16,285 base Not Found: /favicon.ico
WARNING 2018-01-17 16:08:16,289 base Not Found: /favicon.ico
WARNING 2018-01-17 16:08:20,402 base Not Found: /favicon.ico
WARNING 2018-01-17 16:08:20,425 base Not Found: /favicon.ico
WARNING 2018-01-17 16:08:20,486 base Not Found: /favicon.ico
WARNING 2018-01-17 16:08:20,506 base Not Found: /favicon.ico
WARNING 2018-01-17 16:09:26,216 base Not Found: /favicon.ico
ERROR 2018-01-17 16:09:26,877 base Internal Server Error: /
Traceback (most recent call last):
  File "/usr/local/lib/python2.7/site-packages/django/core/handlers/base.py", line 149, in get_response
    response = self.process_exception_by_middleware(e, request)
  File "/usr/local/lib/python2.7/site-packages/django/core/handlers/base.py", line 147, in get_response
    response = wrapped_callback(request, *callback_args, **callback_kwargs)
  File "/usr/local/lib/python2.7/site-packages/django/views/generic/base.py", line 68, in view
    return self.dispatch(request, *args, **kwargs)
  File "/usr/local/lib/python2.7/site-packages/django/views/generic/base.py", line 88, in dispatch
    return handler(request, *args, **kwargs)
  File "/root/weixinweb/apps/mobile/views.py", line 85, in get
    user = authenticate(username=username, password='love.1993')
  File "/usr/local/lib/python2.7/site-packages/django/contrib/auth/__init__.py", line 74, in authenticate
    user = backend.authenticate(**credentials)
  File "/usr/local/lib/python2.7/site-packages/django/contrib/auth/backends.py", line 17, in authenticate
    user = UserModel._default_manager.get_by_natural_key(username)
  File "/usr/local/lib/python2.7/site-packages/django/contrib/auth/base_user.py", line 45, in get_by_natural_key
    return self.get(**{self.model.USERNAME_FIELD: username})
  File "/usr/local/lib/python2.7/site-packages/django/db/models/manager.py", line 122, in manager_method
    return getattr(self.get_queryset(), name)(*args, **kwargs)
  File "/usr/local/lib/python2.7/site-packages/django/db/models/query.py", line 381, in get
    num = len(clone)
  File "/usr/local/lib/python2.7/site-packages/django/db/models/query.py", line 240, in __len__
    self._fetch_all()
  File "/usr/local/lib/python2.7/site-packages/django/db/models/query.py", line 1074, in _fetch_all
    self._result_cache = list(self.iterator())
  File "/usr/local/lib/python2.7/site-packages/django/db/models/query.py", line 52, in __iter__
    results = compiler.execute_sql()
  File "/usr/local/lib/python2.7/site-packages/django/db/models/sql/compiler.py", line 837, in execute_sql
    sql, params = self.as_sql()
  File "/usr/local/lib/python2.7/site-packages/django/db/models/sql/compiler.py", line 389, in as_sql
    where, w_params = self.compile(self.where) if self.where is not None else ("", [])
  File "/usr/local/lib/python2.7/site-packages/django/db/models/sql/compiler.py", line 366, in compile
    sql, params = node.as_sql(self, self.connection)
  File "/usr/local/lib/python2.7/site-packages/django/db/models/sql/where.py", line 79, in as_sql
    sql, params = compiler.compile(child)
  File "/usr/local/lib/python2.7/site-packages/django/db/models/sql/compiler.py", line 366, in compile
    sql, params = node.as_sql(self, self.connection)
  File "/usr/local/lib/python2.7/site-packages/django/db/models/lookups.py", line 157, in as_sql
    lhs_sql, params = self.process_lhs(compiler, connection)
  File "/usr/local/lib/python2.7/site-packages/django/db/models/lookups.py", line 150, in process_lhs
    db_type = self.lhs.output_field.db_type(connection=connection)
  File "/usr/local/lib/python2.7/site-packages/django/db/models/fields/__init__.py", line 625, in db_type
    return connection.data_types[self.get_internal_type()] % data
  File "/usr/local/lib/python2.7/site-packages/django/utils/functional.py", line 33, in __get__
    res = instance.__dict__[self.name] = self.func(instance)
  File "/usr/local/lib/python2.7/site-packages/django/db/backends/mysql/base.py", line 184, in data_types
    if self.features.supports_microsecond_precision:
  File "/usr/local/lib/python2.7/site-packages/django/utils/functional.py", line 33, in __get__
    res = instance.__dict__[self.name] = self.func(instance)
  File "/usr/local/lib/python2.7/site-packages/django/db/backends/mysql/features.py", line 53, in supports_microsecond_precision
    return self.connection.mysql_version >= (5, 6, 4) and Database.version_info >= (1, 2, 5)
  File "/usr/local/lib/python2.7/site-packages/django/utils/functional.py", line 33, in __get__
    res = instance.__dict__[self.name] = self.func(instance)
  File "/usr/local/lib/python2.7/site-packages/django/db/backends/mysql/base.py", line 359, in mysql_version
    with self.temporary_connection():
  File "/usr/local/lib/python2.7/contextlib.py", line 17, in __enter__
    return self.gen.next()
  File "/usr/local/lib/python2.7/site-packages/django/db/backends/base/base.py", line 564, in temporary_connection
    cursor = self.cursor()
  File "/usr/local/lib/python2.7/site-packages/django/db/backends/base/base.py", line 231, in cursor
    cursor = self.make_debug_cursor(self._cursor())
  File "/usr/local/lib/python2.7/site-packages/django/db/backends/base/base.py", line 204, in _cursor
    self.ensure_connection()
  File "/usr/local/lib/python2.7/site-packages/django/db/backends/base/base.py", line 199, in ensure_connection
    self.connect()
  File "/usr/local/lib/python2.7/site-packages/django/db/utils.py", line 95, in __exit__
    six.reraise(dj_exc_type, dj_exc_value, traceback)
  File "/usr/local/lib/python2.7/site-packages/django/db/backends/base/base.py", line 199, in ensure_connection
    self.connect()
  File "/usr/local/lib/python2.7/site-packages/django/db/backends/base/base.py", line 171, in connect
    self.connection = self.get_new_connection(conn_params)
  File "/usr/local/lib/python2.7/site-packages/django/db/backends/mysql/base.py", line 264, in get_new_connection
    conn = Database.connect(**conn_params)
  File "/usr/local/lib/python2.7/site-packages/MySQLdb/__init__.py", line 81, in Connect
    return Connection(*args, **kwargs)
  File "/usr/local/lib/python2.7/site-packages/MySQLdb/connections.py", line 193, in __init__
    super(Connection, self).__init__(*args, **kwargs2)
OperationalError: (2003, "Can't connect to MySQL server on '127.0.0.1' (111)")
WARNING 2018-01-17 16:09:27,479 base Not Found: /favicon.ico
ERROR 2018-01-17 16:09:43,237 base Internal Server Error: /
Traceback (most recent call last):
  File "/usr/local/lib/python2.7/site-packages/django/core/handlers/base.py", line 149, in get_response
    response = self.process_exception_by_middleware(e, request)
  File "/usr/local/lib/python2.7/site-packages/django/core/handlers/base.py", line 147, in get_response
    response = wrapped_callback(request, *callback_args, **callback_kwargs)
  File "/usr/local/lib/python2.7/site-packages/django/views/generic/base.py", line 68, in view
    return self.dispatch(request, *args, **kwargs)
  File "/usr/local/lib/python2.7/site-packages/django/views/generic/base.py", line 88, in dispatch
    return handler(request, *args, **kwargs)
  File "/root/weixinweb/apps/mobile/views.py", line 85, in get
    user = authenticate(username=username, password='love.1993')
  File "/usr/local/lib/python2.7/site-packages/django/contrib/auth/__init__.py", line 74, in authenticate
    user = backend.authenticate(**credentials)
  File "/usr/local/lib/python2.7/site-packages/django/contrib/auth/backends.py", line 17, in authenticate
    user = UserModel._default_manager.get_by_natural_key(username)
  File "/usr/local/lib/python2.7/site-packages/django/contrib/auth/base_user.py", line 45, in get_by_natural_key
    return self.get(**{self.model.USERNAME_FIELD: username})
  File "/usr/local/lib/python2.7/site-packages/django/db/models/manager.py", line 122, in manager_method
    return getattr(self.get_queryset(), name)(*args, **kwargs)
  File "/usr/local/lib/python2.7/site-packages/django/db/models/query.py", line 381, in get
    num = len(clone)
  File "/usr/local/lib/python2.7/site-packages/django/db/models/query.py", line 240, in __len__
    self._fetch_all()
  File "/usr/local/lib/python2.7/site-packages/django/db/models/query.py", line 1074, in _fetch_all
    self._result_cache = list(self.iterator())
  File "/usr/local/lib/python2.7/site-packages/django/db/models/query.py", line 52, in __iter__
    results = compiler.execute_sql()
  File "/usr/local/lib/python2.7/site-packages/django/db/models/sql/compiler.py", line 837, in execute_sql
    sql, params = self.as_sql()
  File "/usr/local/lib/python2.7/site-packages/django/db/models/sql/compiler.py", line 389, in as_sql
    where, w_params = self.compile(self.where) if self.where is not None else ("", [])
  File "/usr/local/lib/python2.7/site-packages/django/db/models/sql/compiler.py", line 366, in compile
    sql, params = node.as_sql(self, self.connection)
  File "/usr/local/lib/python2.7/site-packages/django/db/models/sql/where.py", line 79, in as_sql
    sql, params = compiler.compile(child)
  File "/usr/local/lib/python2.7/site-packages/django/db/models/sql/compiler.py", line 366, in compile
    sql, params = node.as_sql(self, self.connection)
  File "/usr/local/lib/python2.7/site-packages/django/db/models/lookups.py", line 157, in as_sql
    lhs_sql, params = self.process_lhs(compiler, connection)
  File "/usr/local/lib/python2.7/site-packages/django/db/models/lookups.py", line 150, in process_lhs
    db_type = self.lhs.output_field.db_type(connection=connection)
  File "/usr/local/lib/python2.7/site-packages/django/db/models/fields/__init__.py", line 625, in db_type
    return connection.data_types[self.get_internal_type()] % data
  File "/usr/local/lib/python2.7/site-packages/django/utils/functional.py", line 33, in __get__
    res = instance.__dict__[self.name] = self.func(instance)
  File "/usr/local/lib/python2.7/site-packages/django/db/backends/mysql/base.py", line 184, in data_types
    if self.features.supports_microsecond_precision:
  File "/usr/local/lib/python2.7/site-packages/django/utils/functional.py", line 33, in __get__
    res = instance.__dict__[self.name] = self.func(instance)
  File "/usr/local/lib/python2.7/site-packages/django/db/backends/mysql/features.py", line 53, in supports_microsecond_precision
    return self.connection.mysql_version >= (5, 6, 4) and Database.version_info >= (1, 2, 5)
  File "/usr/local/lib/python2.7/site-packages/django/utils/functional.py", line 33, in __get__
    res = instance.__dict__[self.name] = self.func(instance)
  File "/usr/local/lib/python2.7/site-packages/django/db/backends/mysql/base.py", line 359, in mysql_version
    with self.temporary_connection():
  File "/usr/local/lib/python2.7/contextlib.py", line 17, in __enter__
    return self.gen.next()
  File "/usr/local/lib/python2.7/site-packages/django/db/backends/base/base.py", line 564, in temporary_connection
    cursor = self.cursor()
  File "/usr/local/lib/python2.7/site-packages/django/db/backends/base/base.py", line 231, in cursor
    cursor = self.make_debug_cursor(self._cursor())
  File "/usr/local/lib/python2.7/site-packages/django/db/backends/base/base.py", line 204, in _cursor
    self.ensure_connection()
  File "/usr/local/lib/python2.7/site-packages/django/db/backends/base/base.py", line 199, in ensure_connection
    self.connect()
  File "/usr/local/lib/python2.7/site-packages/django/db/utils.py", line 95, in __exit__
    six.reraise(dj_exc_type, dj_exc_value, traceback)
  File "/usr/local/lib/python2.7/site-packages/django/db/backends/base/base.py", line 199, in ensure_connection
    self.connect()
  File "/usr/local/lib/python2.7/site-packages/django/db/backends/base/base.py", line 171, in connect
    self.connection = self.get_new_connection(conn_params)
  File "/usr/local/lib/python2.7/site-packages/django/db/backends/mysql/base.py", line 264, in get_new_connection
    conn = Database.connect(**conn_params)
  File "/usr/local/lib/python2.7/site-packages/MySQLdb/__init__.py", line 81, in Connect
    return Connection(*args, **kwargs)
  File "/usr/local/lib/python2.7/site-packages/MySQLdb/connections.py", line 193, in __init__
    super(Connection, self).__init__(*args, **kwargs2)
OperationalError: (2003, "Can't connect to MySQL server on '127.0.0.1' (111)")
INFO 2018-01-17 16:10:40,790 views 用户[sunyange]登录成功!
WARNING 2018-01-17 16:10:41,460 base Not Found: /favicon.ico
INFO 2018-01-17 16:11:10,466 views 用户[sunyange]登录成功!
WARNING 2018-01-17 16:21:21,811 base Not Found: /favicon.ico
INFO 2018-01-17 17:06:14,502 views 用户[tangjun]登录成功!
INFO 2018-01-17 17:06:34,584 views 用户[tangjun]登录成功!
